<mujoco model="simple_arm">
    <compiler angle="radian"/>
    <default>
        <!-- Fusion 360 の座標系を MuJoCo に変換します -->
        <geom type="mesh" xyaxes="1 0 0 0 0 1"/>
        <joint type="hinge" limited="true" axis="0 1 0"/>
        <position ctrllimited="true" kp="1" kv="0.2"/>
    </default>

    <asset>
        <texture name="grid" type="2d" builtin="checker" rgb1=".1 .2 .3" rgb2=".2 .3 .4" width="300" height="300"/>
        <material name="grid" texture="grid" texrepeat="8 8" reflectance=".2"/>
        <mesh name="base" file="stl/base.stl" scale=".001 .001 .001"/>
        <mesh name="link1" file="stl/link1.stl" scale=".001 .001 .001"/>
        <mesh name="link2" file="stl/link2.stl" scale=".001 .001 .001"/>
    </asset>

    <worldbody>
        <!-- Adjusted floor geom with xyaxes to ensure horizontal alignment -->
        <geom name="floor" type="plane" pos="0 0 0" size="5 5 0.1" material="grid" xyaxes="1 0 0 0 1 0"/>
        <light name="top" pos="0 0 2" diffuse="1 1 1" specular=".5 .5 .5" attenuation=".1 .1 .1"/>

        <body name="base">
            <geom mesh="base"/>
            <body name="link1">
                <joint name="joint1" pos=".1 -.015 .05" axis="0 1 0" range="-0.78 0.78"/>
                <geom mesh="link1"/>
                <body name="link2">
                    <joint name="joint2" pos=".1583 -.01 .1994" axis="0 1 0" range="-1.57 1.57"/>
                    <geom mesh="link2"/>
                </body>
            </body>
        </body>
    </worldbody>

    <actuator>
        <position name="joint1" joint="joint1" ctrlrange="-0.78 0.78"/>
        <position name="joint2" joint="joint2" ctrlrange="-1.57 1.57"/>
    </actuator>

    <contact>
        <exclude body1="base" body2="link1"/>
        <exclude body1="link1" body2="link2"/>
    </contact>
</mujoco>
